Workbook

Sheet Borrador
C3: GASTOS FIJOS MENSUALES (JUEVES/DOMINGO) | G3: GASTOS FIJOS MENSUALES (MARTES/DOMINGO) | J3: GASTOS FIJOS MENSUALES (MARTES/DOMINGO DOMI)
C4: Concepto | D4: Monto | G4: Concepto | H4: Monto | J4: Concepto | K4: Monto
C5: Arriendo | D5: 250000 | G5: Arriendo | H5: 250000 | J5: Arriendo | K5: 250000
C6: Gas | D6: 100000 | G6: Gas | H6: 100000 | J6: Gas | K6: 100000
C7: Publicidad/Marketing | D7: 100000 | G7: Publicidad/Marketing | H7: 100000 | J7: Publicidad/Marketing | K7: 100000
C8: Nómina juev a dom | D8: 1283732 | G8: Nómina martes a dom | H8: 1809008 | J8: Nómina martes a dom | K8: 3618016
C9: Aseo (2 mensual, 60 c/u) | D9: 120000 | G9: Aseo (2 mensual, 60 c/u) | H9: 120000 | J9: Aseo (2 mensual, 60 c/u) | K9: 120000
C10: Plan celular | D10: 30000 | G10: Plan celular | H10: 30000 | J10: Plan celular | K10: 30000
C11: Reserva | D11: 320000 | G11: Reserva | H11: 500000 | J11: Reserva | K11: 500000
C12: Total | D12: =SUM(D5:D11) -> 2203732 | G12: Total | H12: =SUM(H5:H11) -> 2909008 | J12: Total | K12: =SUM(K5:K11) -> 4718016
C15: Capital de trabajo inicial (estimado) JUEVES/DOMINGO. | G15: Capital de trabajo inicial (estimado) martes/domingo | J15: GASTOS FIJOS MENSUALES (JUEVES/DOMINGO DOMI)
C16: Concepto | D16: Monto | G16: Concepto | H16: Monto | J16: Concepto | K16: Monto
C17: Consumibles comida/emp | D17: 2300000 | G17: Consumibles comida/emp | H17: 3450000 | J17: Arriendo | K17: 250000
C18: Gasolina | D18: 150000 | J18: Gas | K18: 100000
C19: Soat y tecno | D19: 50000 | J19: Publicidad/Marketing | K19: 100000
J20: Nómina juev a dom | K20: 2567464
G21: Fondo de mantenimiento de activos | J21: Aseo (2 mensual, 60 c/u) | K21: 120000
G22: Concepto | H22: monto | J22: Plan celular | K22: 30000
G23: Moto | H23: 600000 | J23: Reserva | K23: 400000
G24: Nevera | H24: 200000 | J24: Total | K24: =SUM(K17:K23) -> 3567464
G25: Motor campana | H25: 200000
G26: Remplasos de utencilios | H26: 500000
G27: General | H27: 1000000
C29: Capital inicial (Una vez) | G29: Fondo de emergencia
C30: Concepto | D30: Monto | G30: No se toca si no pasa nada serio
C31: Moto | D31: 3000000 | G31: Monto -> | H31: 1000000
C32: Casco | D32: 200000
C33: Caja menor | D33: 150000
C34: Publicidad de apertura | D34: 350000
C35: 3 meses de arriendo | D35: 750000
C36: 3 meses de sueldo | D36: 3851196 | E36: ó | F36: 5427024
C37: Soporte para celular del dom | D37: 40000
C38: Celular | D38: 200000
C39: Total | D39: =SUM(D31:D38) -> 8541196
C43: Si quisiera vender mi primera hamburguesa hoy deberia tener... | G43: Si quisiera vender mi primera hamburguesa hoy debería tener… (mínimo posible)
C44: concepto | D44: Valor/Coste | E44: Prioridad | G44: concepto | H44: Valor/Coste | I44: Prioridad
C45: Moto/papeles/primer tanque | D45: 3000000 | E45: Alta | G45: Moto/papeles/primer tanque | H45: 2000000 | I45: Alta
C46: Casco | D46: 200000 | E46: Alta | G46: Casco | H46: 150000 | I46: Alta
C47: Soporte para celular | D47: 20000 | E47: Media | G47: Soporte para celular | H47: 15000 | I47: Media
C48: 2 celulares del negocio | D48: 400000 | E48: Alta | G48: Celular exclusivo del negcio | H48: 0 | I48: Alta
...

Sheet Capital Inicial
A1: CAPITAL INICIAL — ESCENARIO MÍNIMO
A2: Inversión única para poder abrir. La moto, el inventario inicial y la publicidad de apertura NO son gastos mensuales recurrentes (ver Documento Maestro secciones 4-5).
A3: Concepto | B3: Monto | C3: Prioridad | D3: Nota
A4: Moto/papeles/primer tanque | B4: 2000000 | C4: Alta | D4: Inversión, no gasto mensual
A5: Casco | B5: 150000 | C5: Alta
A6: Soporte para celular del domiciliario | B6: 15000 | C6: Media
A7: Celular exclusivo del negocio | B7: 0 | C7: Alta | D7: Si ya se tiene, costo 0
A8: Inventario inicial de comida | B8: 500000 | C8: Crítica | D8: NO es el consumo de un mes; es el mínimo para empezar a vender (Documento Maestro sección 4)
A9: Empaques | B9: 100000 | C9: Crítica
A10: Publicidad de apertura | B10: 350000 | C10: Crítica | D10: Cifra provisional — pendiente definir con marketing (hermano de Diego)
A11: Nómina inicial | B11: 1000000 | C11: Crítica
A12: Arriendo inicial (servicios/utilidades) | B12: 250000 | C12: Crítica | D12: El papá de Diego no cobra arriendo comercial
A13: Gas/servicios inicial | B13: 100000 | C13: Media
A14: TOTAL CAPITAL INICIAL | B14: =SUM(B4:B13) -> 4465000
A16: El fondo de mantenimiento y el fondo de emergencia se manejan como aportes MENSUALES en la hoja 'Operación Mensual' (Tabla 5 - Fondos), no como parte de este capital inicial de apertura.

Sheet Proyección de Ventas
A1: PROYECCIÓN DE VENTAS
A2: Escenario de trabajo (Documento Maestro sección 9), no una predicción. Ajustar apenas existan datos reales de venta.
A4: Días abiertos/mes | B4: 26
A5: Hamburguesas/día (objetivo) | B5: 20
A6: TOTAL HAMBURGUESAS/MES | B6: =B4*B5 -> 520
A9: Producto | B9: % distribución | C9: Hamburguesas/mes | D9: Precio de venta ($) | E9: Ventas ($)
A10: Clásica | B10: 0.6 | C10: =$B$6*B10 -> 312 | D10: ='Food Cost'!$D$44 -> 22100 | E10: =C10*D10 -> 6895200
A11: Montañera | B11: 0.25 | C11: =$B$6*B11 -> 130 | D11: ='Food Cost'!$D$46 -> 29100 | E11: =C11*D11 -> 3783000
A12: Cheese | B12: 0.15 | C12: =$B$6*B12 -> 78 | D12: ='Food Cost'!$D$45 -> 31900 | E12: =C12*D12 -> 2488200
A13: Total | B13: =SUM(B10:B12) -> 1 | C13: =SUM(C10:C12) -> 520 | E13: =SUM(E10:E12) -> 13166400
A15: Ticket promedio | B15: =E13/C13 -> 25320

Sheet Recetas Base
A1: RECETAS BASE (preparaciones reutilizables)
A2: Concepto clave del Documento Maestro (sección 12): en vez de recalcular cada ingrediente por hamburguesa, cada hamburguesa consume una porción de una receta base ya costeada.
A4: 1. Carne preparada
A5: Ingrediente | B5: Cantidad (g) | D5: Nota
A6: Carne (cruda) | B6: 575
A7: Cebolla | B7: 125
A8: Especias/salsas de sazón | B8: 35
A9: Total mezcla (g) | B9: =SUM(B6:B8) -> 735
A10: Costo total de la receta ($) | B10: 16900 | D10: Dato de receta anterior verificada (Documento Maestro sección 11). Insumos crudos aún no desglosados por costo unitario.
A11: Rendimiento (hamburguesas) | B11: 5
A12: Costo por hamburguesa ($) | B12: =B10/B11 -> 3380
A13: Costo por gramo de mezcla ($/g) | B13: =B10/B9 -> 22.993197
A15: 2. Cebolla caramelizada
A16: Costo mensual estimado ($) | B16: 90000 | D16: Fuente: tabla de compras mensuales original (Documento Maestro sección 13)
A17: Porciones mensuales (tabla original) | B17: 156
A18: Costo por porción ($) | B18: =B16/B17 -> 576.92308
A19: ⚠ REVISAR: Clásica + Cheese suman 390 hamburguesas/mes. Si cada una lleva 1 porción, se necesitan ~390 porciones/mes, no 156. La hoja 'Compras Mensuales' ya recalcula la cantidad real necesaria — falta validar el tamaño real de la porción con el proveedor/receta.
A21: 3. Hogao
A22: Costo mensual estimado ($) | B22: 85000
A23: Porciones mensuales (tabla original) | B23: 130
A24: Costo por porción ($) | B24: =B22/B23 -> 653.84615
A25: Consistente: Montañera vende 130/mes = 130 porciones, es decir 1 porción por hamburguesa. Sin inconsistencia detectada.
A27: 4. Salsas (BBQ + salsa dulce combinadas)
A28: Costo mensual estimado ($) | B28: 200000
A29: Hamburguesas/mes que llevan salsa | B29: ='Proyección de Ventas'!$B$6 -> 520
A30: Costo por hamburguesa ($) | B30: =B28/B29 -> 384.61538
A31: ⚠ SUPUESTO: no existe todavía una receta detallada de salsas (BBQ, dulce, chipotle, miel picante). Se prorratea el gasto mensual estimado entre el total de hamburguesas. Definir la receta real de cada salsa para afinar este costo.

Sheet Costos Unitarios
A1: COSTOS UNITARIOS DE INSUMOS
A2: Costo por unidad de cada insumo, usado por la hoja Food Cost para calcular el costo de cada hamburguesa.
A3: Insumo | B3: Unidad | C3: Costo unitario | D3: Fuente / nota
A4: Carne preparada | B4: $/hamburguesa | C4: ='Recetas Base'!$B$12 -> 3380 | D4: Receta base: 735 g rinden 5 hamburguesas (ver hoja Recetas Base)
A5: Pan | B5: $/unidad | C5: 1300 | D5: 676.000 ÷ 520 unidades
A6: Queso blanco | B6: $/loncha | C6: 225 | D6: 234.000 ÷ 1.040 lonchas
A7: Queso cheddar | B7: $/loncha | C7: 700 | D7: 109.200 ÷ 156 lonchas (solo Cheese)
A8: Queso crema | B8: $/g | C8: 51 | D8: 119.340 ÷ 2.340 g (solo Cheese)
A9: Chorizo santarrosano | B9: $/unidad | C9: 2000 | D9: 260.000 ÷ 130 unidades (solo Montañera)
A10: Tomate | B10: $/unidad (receta) | C10: 900 | D10: 234.000 ÷ 260 unidades — ⚠ convertir a kg/unidad comercial en Compras Mensuales
A11: Lechuga | B11: $/hoja (receta) | C11: 50 | D11: 52.000 ÷ 1.040 hojas — ⚠ convertir a unidad comercial en Compras Mensuales
A12: Cebolla caramelizada | B12: $/porción | C12: ='Recetas Base'!$B$18 -> 576.92308 | D12: Ver hoja Recetas Base — cantidad mensual real a validar
A13: Hogao | B13: $/porción | C13: ='Recetas Base'!$B$24 -> 653.84615 | D13: Ver hoja Recetas Base
A14: Salsas (BBQ + dulce) | B14: $/hamburguesa | C14: ='Recetas Base'!$B$30 -> 384.61538 | D14: Ver hoja Recetas Base — provisional, sin receta detallada
A15: Cilantro | B15: $/g | C15: 51 | D15: 3.300 ÷ 65 g (redondeado, solo Montañera)
A17: Consumibles (empaque — no es food cost)
A18: Insumo | B18: Unidad | C18: Costo unitario | D18: Fuente / nota
A19: Cajas | B19: $/unidad | C19: 1363.4615 | D19: 709.000 ÷ 520 unidades
A20: Papel encerado | B20: $/unidad | C20: 137 | D20: 71.240 ÷ 520 unidades
A21: Servilletas | B21: $/unidad | C21: 38.461538 | D21: 20.000 ÷ 520 unidades
A22: Bolsas | B22: $/unidad | C22: 115.38462 | D22: 60.000 ÷ 520 unidades
A23: Bolsa kraft L | B23: $/unidad | C23: 32.115385 | D23: 16.700 ÷ 520 unidades

Sheet Food Cost
A1: FOOD COST — LAS TRES HAMBURGUESAS
A3: CLÁSICA
A4: Ingrediente | B4: Cantidad/hamburguesa | C4: Unidad | D4: Costo unitario | E4: Subtotal
A5: Pan | B5: 1 | C5: unidad | D5: ='Costos Unitarios'!$C$5 -> 1300 | E5: =B5*D5 -> 1300
A6: Carne preparada | B6: 1 | C6: hamburguesa | D6: ='Costos Unitarios'!$C$4 -> 3380 | E6: =B6*D6 -> 3380
A7: Tomate | B7: 0.5 | C7: unidad | D7: ='Costos Unitarios'!$C$10 -> 900 | E7: =B7*D7 -> 450
A8: Lechuga | B8: 2 | C8: hoja | D8: ='Costos Unitarios'!$C$11 -> 50 | E8: =B8*D8 -> 100
A9: Cebolla caramelizada | B9: 1 | C9: porción | D9: ='Costos Unitarios'!$C$12 -> 576.92308 | E9: =B9*D9 -> 576.92308
A10: Queso blanco | B10: 2 | C10: loncha | D10: ='Costos Unitarios'!$C$6 -> 225 | E10: =B10*D10 -> 450
A11: Salsas (BBQ + dulce) | B11: 1 | C11: hamburguesa | D11: ='Costos Unitarios'!$C$14 -> 384.61538 | E11: =B11*D11 -> 384.61538
A12: TOTAL COSTO CLÁSICA | E12: =SUM(E5:E11) -> 6641.5385
A14: CHEESE
A15: Ingrediente | B15: Cantidad/hamburguesa | C15: Unidad | D15: Costo unitario | E15: Subtotal
A16: Pan | B16: 1 | C16: unidad | D16: ='Costos Unitarios'!$C$5 -> 1300 | E16: =B16*D16 -> 1300
A17: Carne preparada | B17: 1 | C17: hamburguesa | D17: ='Costos Unitarios'!$C$4 -> 3380 | E17: =B17*D17 -> 3380
A18: Tomate | B18: 0.5 | C18: unidad | D18: ='Costos Unitarios'!$C$10 -> 900 | E18: =B18*D18 -> 450
A19: Lechuga | B19: 2 | C19: hoja | D19: ='Costos Unitarios'!$C$11 -> 50 | E19: =B19*D19 -> 100
A20: Cebolla caramelizada | B20: 1 | C20: porción | D20: ='Costos Unitarios'!$C$12 -> 576.92308 | E20: =B20*D20 -> 576.92308
A21: Queso blanco | B21: 2 | C21: loncha | D21: ='Costos Unitarios'!$C$6 -> 225 | E21: =B21*D21 -> 450
A22: Queso crema | B22: 30 | C22: g | D22: ='Costos Unitarios'!$C$8 -> 51 | E22: =B22*D22 -> 1530
A23: Queso cheddar | B23: 2 | C23: loncha | D23: ='Costos Unitarios'!$C$7 -> 700 | E23: =B23*D23 -> 1400
A24: Salsas (BBQ + dulce) | B24: 1 | C24: hamburguesa | D24: ='Costos Unitarios'!$C$14 -> 384.61538 | E24: =B24*D24 -> 384.61538
A25: TOTAL COSTO CHEESE | E25: =SUM(E16:E24) -> 9571.5385
A27: MONTAÑERA
A28: Ingrediente | B28: Cantidad/hamburguesa | C28: Unidad | D28: Costo unitario | E28: Subtotal
A29: Pan | B29: 1 | C29: unidad | D29: ='Costos Unitarios'!$C$5 -> 1300 | E29: =B29*D29 -> 1300
A30: Carne preparada | B30: 1 | C30: hamburguesa | D30: ='Costos Unitarios'!$C$4 -> 3380 | E30: =B30*D30 -> 3380
A31: Tomate | B31: 0.5 | C31: unidad | D31: ='Costos Unitarios'!$C$10 -> 900 | E31: =B31*D31 -> 450
A32: Lechuga | B32: 2 | C32: hoja | D32: ='Costos Unitarios'!$C$11 -> 50 | E32: =B32*D32 -> 100
A33: Hogao | B33: 1 | C33: porción | D33: ='Costos Unitarios'!$C$13 -> 653.84615 | E33: =B33*D33 -> 653.84615
A34: Queso blanco | B34: 2 | C34: loncha | D34: ='Costos Unitarios'!$C$6 -> 225 | E34: =B34*D34 -> 450
A35: Salsas (BBQ + dulce) | B35: 1 | C35: hamburguesa | D35: ='Costos Unitarios'!$C$14 -> 384.61538 | E35: =B35*D35 -> 384.61538
A36: Cilantro | B36: 0.5 | C36: g | D36: ='Costos Unitarios'!$C$15 -> 51 | E36: =B36*D36 -> 25.5
A37: Chorizo santarrosano | B37: 1 | C37: unidad | D37: ='Costos Unitarios'!$C$9 -> 2000 | E37: =B37*D37 -> 2000
A38: TOTAL COSTO MONTAÑERA | E38: =SUM(E29:E37) -> 8743.9615
A40: PRECIOS DE VENTA SUGERIDOS
A41: Food cost objetivo (%) | B41: 0.3 | C41: Editable — estándar del sector: 28%-33%
A43: Producto | B43: Costo/hamburguesa | C43: Precio sugerido (costo/%) | D43: Precio final a usar | E43: Margen contribución
A44: Clásica | B44: =E12 -> 6641.5385 | C44: =B44/$B$41 -> 22138.462 | D44: =MROUND(C44,100) -> 22100 | E44: =D44-B44 -> 15458.462
A45: Cheese | B45: =E25 -> 9571.5385 | C45: =B45/$B$41 -> 31905.128 | D45: =MROUND(C45,100) -> 31900 | E45: =D45-B45 -> 22328.462
...

Sheet Compras Mensuales
A1: COMPRAS MENSUALES ESTIMADAS (fórmula, ligada a Proyección de Ventas)
A2: El costo total ($) se calcula con el costo por unidad de receta (columna H), que es confiable. Las columnas F/G (unidad de compra) son para planear cuánto pedirle al proveedor — ajusta el factor de conversión cuando confirmes con cada proveedor.
A4: Insumo | B4: Volumen aplicable (hamb/mes) | C4: Cantidad/hamburguesa | D4: Unidad receta | E4: Cantidad necesaria/mes | F4: Factor conversión a unidad compra | G4: Cantidad a comprar | H4: Unidad compra | I4: Costo unitario (receta) | J4: Costo total mensual
A5: Carne preparada (mezcla) | B5: ='Proyección de Ventas'!$B$6 -> 520 | C5: 147 | D5: g | E5: =B5*C5 -> 76440 | F5: 1 | G5: =E5*F5 -> 76440 | H5: g | I5: ='Costos Unitarios'!$C$4/147 -> 22.993197 | J5: =E5*I5 -> 1757600
A6: Pan | B6: ='Proyección de Ventas'!$B$6 -> 520 | C6: 1 | D6: unidad | E6: =B6*C6 -> 520 | F6: 1 | G6: =E6*F6 -> 520 | H6: unidad | I6: ='Costos Unitarios'!$C$5 -> 1300 | J6: =E6*I6 -> 676000
A7: Queso blanco | B7: ='Proyección de Ventas'!$B$6 -> 520 | C7: 2 | D7: loncha | E7: =B7*C7 -> 1040 | F7: 1 | G7: =E7*F7 -> 1040 | H7: loncha | I7: ='Costos Unitarios'!$C$6 -> 225 | J7: =E7*I7 -> 234000
A8: Queso cheddar | B8: ='Proyección de Ventas'!$C$12 -> 78 | C8: 2 | D8: loncha | E8: =B8*C8 -> 156 | F8: 1 | G8: =E8*F8 -> 156 | H8: loncha | I8: ='Costos Unitarios'!$C$7 -> 700 | J8: =E8*I8 -> 109200 | K8: Solo Cheese
A9: Queso crema | B9: ='Proyección de Ventas'!$C$12 -> 78 | C9: 30 | D9: g | E9: =B9*C9 -> 2340 | F9: 1 | G9: =E9*F9 -> 2340 | H9: g | I9: ='Costos Unitarios'!$C$8 -> 51 | J9: =E9*I9 -> 119340 | K9: Solo Cheese
A10: Chorizo santarrosano | B10: ='Proyección de Ventas'!$C$11 -> 130 | C10: 1 | D10: unidad | E10: =B10*C10 -> 130 | F10: 1 | G10: =E10*F10 -> 130 | H10: unidad | I10: ='Costos Unitarios'!$C$9 -> 2000 | J10: =E10*I10 -> 260000 | K10: Solo Montañera
A11: Tomate | B11: ='Proyección de Ventas'!$B$6 -> 520 | C11: 0.5 | D11: unidad | E11: =B11*C11 -> 260 | F11: 0.15 | G11: =E11*F11 -> 39 | H11: kg | I11: ='Costos Unitarios'!$C$10 -> 900 | J11: =E11*I11 -> 234000 | K11: ⚠ Factor conversión provisional: ~150 g/tomate. Ajustar según el proveedor (vende por kg o por unidad).
A12: Lechuga | B12: ='Proyección de Ventas'!$B$6 -> 520 | C12: 2 | D12: hoja | E12: =B12*C12 -> 1040 | F12: 0.05 | G12: =E12*F12 -> 52 | H12: kg | I12: ='Costos Unitarios'!$C$11 -> 50 | J12: =E12*I12 -> 52000 | K12: ⚠ Factor conversión provisional: ~50 g/hoja. Ajustar según el proveedor.
A13: Cebolla caramelizada | B13: ='Proyección de Ventas'!$C$10+'Proyección de Ventas'!$C$12 -> 390 | C13: 1 | D13: porción | E13: =B13*C13 -> 390 | F13: 1 | G13: =E13*F13 -> 390 | H13: porción | I13: ='Costos Unitarios'!$C$12 -> 576.92308 | J13: =E13*I13 -> 225000 | K13: ⚠ Corregido: antes se estimaban solo 156 porciones/mes; con 1 porción por hamburguesa en Clásica+Cheese se necesitan ~390. Validar tamaño real de porción.
A14: Hogao | B14: ='Proyección de Ventas'!$C$11 -> 130 | C14: 1 | D14: porción | E14: =B14*C14 -> 130 | F14: 1 | G14: =E14*F14 -> 130 | H14: porción | I14: ='Costos Unitarios'!$C$13 -> 653.84615 | J14: =E14*I14 -> 85000 | K14: Solo Montañera — consistente con la tabla original
A15: Salsas (BBQ + dulce) | B15: ='Proyección de Ventas'!$B$6 -> 520 | C15: 1 | D15: hamburguesa | E15: =B15*C15 -> 520 | F15: 1 | G15: =E15*F15 -> 520 | H15: hamburguesa | I15: ='Costos Unitarios'!$C$14 -> 384.61538 | J15: =E15*I15 -> 200000 | K15: ⚠ Provisional — sin receta detallada, ver hoja Recetas Base
A16: Cilantro | B16: ='Proyección de Ventas'!$C$11 -> 130 | C16: 0.5 | D16: g | E16: =B16*C16 -> 65 | F16: 1 | G16: =E16*F16 -> 65 | H16: g | I16: ='Costos Unitarios'!$C$15 -> 51 | J16: =E16*I16 -> 3315 | K16: Solo Montañera
A18: SUBTOTAL INGREDIENTES | J18: =SUM(J5:J16) -> 3955455
A20: CONSUMIBLES (empaque)
A21: Insumo | B21: Volumen aplicable (hamb/mes) | C21: Cantidad/hamburguesa | D21: Unidad | I21: Costo unitario | J21: Costo total mensual
A22: Cajas | B22: ='Proyección de Ventas'!$B$6 -> 520 | C22: 1 | D22: unidad | I22: ='Costos Unitarios'!$C$19 -> 1363.4615 | J22: =B22*C22*I22 -> 709000
A23: Papel encerado | B23: ='Proyección de Ventas'!$B$6 -> 520 | C23: 1 | D23: unidad | I23: ='Costos Unitarios'!$C$20 -> 137 | J23: =B23*C23*I23 -> 71240
A24: Servilletas | B24: ='Proyección de Ventas'!$B$6 -> 520 | C24: 1 | D24: unidad | I24: ='Costos Unitarios'!$C$21 -> 38.461538 | J24: =B24*C24*I24 -> 20000
A25: Bolsas | B25: ='Proyección de Ventas'!$B$6 -> 520 | C25: 1 | D25: unidad | I25: ='Costos Unitarios'!$C$22 -> 115.38462 | J25: =B25*C25*I25 -> 60000
A26: Bolsa kraft L | B26: ='Proyección de Ventas'!$B$6 -> 520 | C26: 1 | D26: unidad | I26: ='Costos Unitarios'!$C$23 -> 32.115385 | J26: =B26*C26*I26 -> 16700
A27: SUBTOTAL CONSUMIBLES | J27: =SUM(J22:J26) -> 876940
A29: TOTAL COMPRAS MENSUALES (ingredientes + consumibles) | J29: =J18+J27 -> 4832395

Sheet Operación Mensual
A1: OPERACIÓN MENSUAL
A2: Escenario martes a domingo (6 días/semana ≈ 26 días/mes), con domicilios — consistente con la Proyección de Ventas.
A4: TABLA 1 — GASTOS FIJOS
A5: Concepto | B5: Monto | D5: Nota
A6: Arriendo (servicios/utilidades) | B6: 250000 | D6: El papá de Diego no cobra arriendo comercial
A7: Gas/luz | B7: 100000
A8: Publicidad/Marketing | B8: 100000 | D8: Recurrente — separado del marketing de apertura
A9: Nómina (martes a domingo, con domicilios) | B9: 3618016 | D9: Ver hoja Borrador para el detalle del cálculo
A10: Aseo (2 x mes, $60.000 c/u) | B10: 120000
A11: Plan celular | B11: 30000
A12: TOTAL GASTOS FIJOS | B12: =SUM(B6:B11) -> 4218016
A14: TABLA 2 — COMPRAS VARIABLES (ingredientes)
A15: Total compras de ingredientes (ver hoja 'Compras Mensuales') | B15: ='Compras Mensuales'!$J$18 -> 3955455
A17: TABLA 3 — CONSUMIBLES
A18: Total consumibles (ver hoja 'Compras Mensuales') | B18: ='Compras Mensuales'!$J$27 -> 876940
A20: TABLA 4 — OPERACIÓN DE DOMICILIOS
A21: Concepto | B21: Monto | D21: Nota
A22: Gasolina | B22: 150000 | D22: ⚠ Provisional — validar con datos reales de consumo de la moto
A23: Lavado | B23: 20000 | D23: ⚠ Provisional
A24: Aceite | B24: 30000 | D24: ⚠ Provisional
A25: Parqueaderos | B25: 0
A26: Otros | B26: 20000 | D26: ⚠ Provisional
A27: TOTAL DOMICILIOS | B27: =SUM(B22:B26) -> 220000
A29: TABLA 5 — FONDOS (no son gastos, es dinero que se aparta)
A30: Concepto | B30: Monto | D30: Nota
A31: Reserva general | B31: 500000
A32: Mantenimiento | B32: 150000 | D32: ⚠ Provisional — ajustar según plan real de mantenimiento (moto, nevera, plancha)
A33: Emergencia | B33: 100000 | D33: ⚠ Provisional — construye hacia la meta de $1.000.000 (ver hoja Borrador)
A34: Crecimiento | B34: 0 | D34: Se activa en Etapa 2+, no en Etapa 0/1
A35: Impuestos | B35: 0 | D35: Definir cuando aplique régimen tributario
A36: TOTAL FONDOS | B36: =SUM(B31:B35) -> 750000
A38: TABLA 6 — RESUMEN: ¿CUÁNTO NECESITA EL NEGOCIO PARA FUNCIONAR AL MES?
A39: TOTAL NECESIDAD MENSUAL | B39: =B12+B15+B18+B27+B36 -> 10020411
A41: TABLA 7 — META DE VENTAS
A42: Días abiertos/mes | B42: ='Proyección de Ventas'!$B$4 -> 26
A43: Hamburguesas/día | B43: ='Proyección de Ventas'!$B$5 -> 20
A44: Hamburguesas/mes | B44: ='Proyección de Ventas'!$B$6 -> 520
A45: Ticket promedio | B45: ='Proyección de Ventas'!$B$15 -> 25320
A46: Ventas mensuales | B46: ='Proyección de Ventas'!$E$13 -> 13166400
A47: Costos totales (Tabla 6) | B47: =B39 -> 10020411
...

Sheet Punto de Equilibrio
A1: PUNTO DE EQUILIBRIO
A2: Responde: ¿cuántas hamburguesas hay que vender al mes para no perder dinero? ¿Y para ganar $X, pagarme sueldo, o contratar a alguien? (Documento Maestro sección 27)
A4: Costos fijos operativos (gastos fijos + domicilios) | B4: ='Operación Mensual'!$B$12+'Operación Mensual'!$B$27 -> 4438016
A5: Fondos (apartados) | B5: ='Operación Mensual'!$B$36 -> 750000
A6: Costos fijos + fondos | B6: =B4+B5 -> 5188016
A8: Costo variable promedio por hamburguesa (ingredientes + consumibles) | B8: =('Compras Mensuales'!$J$18+'Compras Mensuales'!$J$27)/'Proyección de Ventas'!$B$6 -> 9293.0673
A9: Ticket promedio (precio de venta ponderado) | B9: ='Proyección de Ventas'!$B$15 -> 25320
A10: MARGEN DE CONTRIBUCIÓN PROMEDIO / HAMBURGUESA | B10: =B9-B8 -> 16026.933
A12: Punto de equilibrio SIN fondos (unidades/mes) | B12: =B4/B10 -> 276.90988
A13: Punto de equilibrio SIN fondos ($/mes) | B13: =B12*B9 -> 7011358.1
A14: Punto de equilibrio CON fondos (unidades/mes) | B14: =B6/B10 -> 323.70611
A15: Punto de equilibrio CON fondos ($/mes) | B15: =B14*B9 -> 8196238.6
A16: Escenario actual (520 hamburguesas/mes) vs. punto de equilibrio | B16: ='Proyección de Ventas'!$B$6-B14 -> 196.29389 | C16: Positivo = por encima del punto de equilibrio con fondos; negativo = por debajo.
A19: ¿CUÁNTAS HAMBURGUESAS PARA LOGRAR CADA META?
A20: Meta | B20: Utilidad deseada ($) | C20: Hamburguesas/mes necesarias | D20: Nota
A21: Punto de equilibrio (utilidad $0) | B21: 0 | C21: =(B6+B21)/B10 -> 323.70611
A22: Ganar $500.000/mes | B22: 500000 | C22: =(B6+B22)/B10 -> 354.90359
A23: Ganar $1.000.000/mes | B23: 1000000 | C23: =(B6+B23)/B10 -> 386.10108
A24: Pagarme un sueldo | B24: 1500000 | C24: =(B6+B24)/B10 -> 417.29856 | D24: ⚠ Editable — define aquí el sueldo mensual que quieres pagarte
A25: Contratar a otra persona | B25: 1809008 | C25: =(B6+B25)/B10 -> 436.57911 | D25: ⚠ Editable — estimado con la nómina de un turno adicional (ver hoja Borrador)

Sheet Flujo de Caja
A1: FLUJO DE CAJA — PROYECCIÓN SIMPLE (6 MESES)
A2: Usa el mismo escenario mensual repetido (520 hamburguesas/mes) como plantilla. Reemplaza cada mes por datos reales apenas el negocio esté operando.
A4: Concepto | B4: Mes 0 (apertura) | C4: Mes 1 | D4: Mes 2 | E4: Mes 3 | F4: Mes 4 | G4: Mes 5 | H4: Mes 6
A5: Capital inicial invertido | B5: =-'Capital Inicial'!$B$14 -> -4465000 | C5: 0 | D5: 0 | E5: 0 | F5: 0 | G5: 0 | H5: 0
A6: Ventas | B6: 0 | C6: ='Operación Mensual'!$B$46 -> 13166400 | D6: ='Operación Mensual'!$B$46 -> 13166400 | E6: ='Operación Mensual'!$B$46 -> 13166400 | F6: ='Operación Mensual'!$B$46 -> 13166400 | G6: ='Operación Mensual'!$B$46 -> 13166400 | H6: ='Operación Mensual'!$B$46 -> 13166400
A7: Costo variable (ingredientes + consumibles) | B7: 0 | C7: =-('Operación Mensual'!$B$15+'Operación Mensual'!$B$18) -> -4832395 | D7: =-('Operación Mensual'!$B$15+'Operación Mensual'!$B$18) -> -4832395 | E7: =-('Operación Mensual'!$B$15+'Operación Mensual'!$B$18) -> -4832395 | F7: =-('Operación Mensual'!$B$15+'Operación Mensual'!$B$18) -> -4832395 | G7: =-('Operación Mensual'!$B$15+'Operación Mensual'!$B$18) -> -4832395 | H7: =-('Operación Mensual'!$B$15+'Operación Mensual'!$B$18) -> -4832395
A8: Gastos fijos | B8: 0 | C8: =-'Operación Mensual'!$B$12 -> -4218016 | D8: =-'Operación Mensual'!$B$12 -> -4218016 | E8: =-'Operación Mensual'!$B$12 -> -4218016 | F8: =-'Operación Mensual'!$B$12 -> -4218016 | G8: =-'Operación Mensual'!$B$12 -> -4218016 | H8: =-'Operación Mensual'!$B$12 -> -4218016
A9: Domicilios | B9: 0 | C9: =-'Operación Mensual'!$B$27 -> -220000 | D9: =-'Operación Mensual'!$B$27 -> -220000 | E9: =-'Operación Mensual'!$B$27 -> -220000 | F9: =-'Operación Mensual'!$B$27 -> -220000 | G9: =-'Operación Mensual'!$B$27 -> -220000 | H9: =-'Operación Mensual'!$B$27 -> -220000
A10: Fondos apartados | B10: 0 | C10: =-'Operación Mensual'!$B$36 -> -750000 | D10: =-'Operación Mensual'!$B$36 -> -750000 | E10: =-'Operación Mensual'!$B$36 -> -750000 | F10: =-'Operación Mensual'!$B$36 -> -750000 | G10: =-'Operación Mensual'!$B$36 -> -750000 | H10: =-'Operación Mensual'!$B$36 -> -750000
A11: FLUJO NETO DEL MES | B11: =SUM(B5:B10) -> -4465000 | C11: =SUM(C5:C10) -> 3145989 | D11: =SUM(D5:D10) -> 3145989 | E11: =SUM(E5:E10) -> 3145989 | F11: =SUM(F5:F10) -> 3145989 | G11: =SUM(G5:G10) -> 3145989 | H11: =SUM(H5:H10) -> 3145989
A12: CAJA ACUMULADA | B12: =B11 -> -4465000 | C12: =B12+C11 -> -1319011 | D12: =C12+D11 -> 1826978 | E12: =D12+E11 -> 4972967 | F12: =E12+F11 -> 8118956 | G12: =F12+G11 -> 11264945 | H12: =G12+H11 -> 14410934
A14: Si la caja acumulada se vuelve negativa en algún mes, esa es la señal de que el capital inicial o el ritmo de ventas asumido no alcanzan — ajusta el escenario antes de invertir.

Sheet Dashboard
A1: DASHBOARD — PIXEL BURGER
A2: Actualizado con el escenario de trabajo de 520 hamburguesas/mes. Última actualización del modelo: 2026-09-15.
A4: Capital inicial requerido | B4: ='Capital Inicial'!$B$14 -> 4465000
A5: Hamburguesas/mes (escenario) | B5: ='Proyección de Ventas'!$B$6 -> 520
A6: Ticket promedio | B6: ='Proyección de Ventas'!$B$15 -> 25320
A7: Ventas mensuales proyectadas | B7: ='Proyección de Ventas'!$E$13 -> 13166400
A8: Gastos fijos mensuales | B8: ='Operación Mensual'!$B$12 -> 4218016
A9: Compras variables (ingredientes) | B9: ='Operación Mensual'!$B$15 -> 3955455
A10: Consumibles | B10: ='Operación Mensual'!$B$18 -> 876940
A11: Fondos mensuales (apartados) | B11: ='Operación Mensual'!$B$36 -> 750000
A12: Necesidad mensual total | B12: ='Operación Mensual'!$B$39 -> 10020411
A13: Utilidad mensual proyectada | B13: ='Operación Mensual'!$B$48 -> 3145989
A15: Food cost real ponderado | B15: ='Food Cost'!$B$49 -> 0.30042039
A17: Distribución de ventas por producto
A18: Producto | B18: Hamburguesas/mes | C18: Ventas ($)
A19: Clásica | B19: ='Proyección de Ventas'!$C$10 -> 312 | C19: ='Proyección de Ventas'!$E$10 -> 6895200
A20: Montañera | B20: ='Proyección de Ventas'!$C$11 -> 130 | C20: ='Proyección de Ventas'!$E$11 -> 3783000
A21: Cheese | B21: ='Proyección de Ventas'!$C$12 -> 78 | C21: ='Proyección de Ventas'!$E$12 -> 2488200
A23: Punto de equilibrio (unidades/mes, con fondos) | B23: ='Punto de Equilibrio'!B14 -> 323.70611
